Workbook

Sheet Каталог коорд
A1: Система координат | G1: МСК29
A2: Условный номер земельного участка | F2: 29:15:060401:259:ЗУ1
A3: Площадь земельного участка | G3: 599 | H3: м2
A4: Обозначение характерных точек границ | B4: Дирекционный угол | D4: Д. угол в долях | E4: Расстояние | F4: Координаты, м
B5: 0 | C5: / | D5: 0 | E5: М | F5: Х | G5: У
A6: 1 | B6: =IF(D6="","",TRUNC(D6)) -> #VALUE! | C6: =IF(D6="","",(D6-B6)*60) -> #VALUE! | D6: =IF(OR(F6=0,F7=0,G6=0,G7=0),"",IF(AND((G6-G7)<0,(F6-F7)<0),ATAN((G6-G7)/(F6-F7))*180/PI(),IF((F6-F7)>0,180+ATAN((G6-G7)/(F6-F7))*180/PI(),360+ATAN((G6-G7)/(F6-F7))*180/PI()))) -> #VALUE! | E6: =IF(OR(F6=0,F7=0,G6=0,G7=0),"",SQRT(POWER(F6-F7,2)+POWER(G6-G7,2))) -> #VALUE! | F6: =MID(L6,38,9) -> 471494.61 | G6: =MID(L6,22,10) -> 2507730.00 | L6: в точке X=2507730.0000 Y=471494.6100 Z= 1.9400 | S6: , | T6: 105.75 | W6: =CONCATENATE(A6,S6,F6,S6,G6,S6,T6) -> 1,471494.61,2507730.00,105,75
A7: =IF(L7="",IF(L6="","",$A$6),A6+1) -> 2 | B7: =IF(D7="","",TRUNC(D7)) -> #VALUE! | C7: =IF(D7="","",(D7-B7)*60) -> #VALUE! | D7: =IF(OR(F7=0,F8=0,G7=0,G8=0),"",IF(AND((G7-G8)<0,(F7-F8)<0),ATAN((G7-G8)/(F7-F8))*180/PI(),IF((F7-F8)>0,180+ATAN((G7-G8)/(F7-F8))*180/PI(),360+ATAN((G7-G8)/(F7-F8))*180/PI()))) -> #VALUE! | E7: =IF(OR(F7=0,F8=0,G7=0,G8=0),"",SQRT(POWER(F7-F8,2)+POWER(G7-G8,2))) -> #VALUE! | F7: =MID(L7,38,9) -> 471496.36 | G7: =MID(L7,22,10) -> 2507736.28 | L7: в точке X=2507736.2800 Y=471496.3600 Z= 1.9400 | S7: , | T7: 104.717 | W7: =CONCATENATE(A7,S7,F7,S7,G7,S7,T7) -> 2,471496.36,2507736.28,104,717
A8: =IF(L8="",IF(L7="","",$A$6),A7+1) -> 3 | B8: =IF(D8="","",TRUNC(D8)) -> #VALUE! | C8: =IF(D8="","",(D8-B8)*60) -> #VALUE! | D8: =IF(OR(F8="",F9="",G8="",G9=""),"",IF(AND((G8-G9)<0,(F8-F9)<0),ATAN((G8-G9)/(F8-F9))*180/PI(),IF((F8-F9)>0,180+ATAN((G8-G9)/(F8-F9))*180/PI(),360+ATAN((G8-G9)/(F8-F9))*180/PI()))) -> #VALUE! | E8: =IF(OR(F8="",F9="",G8="",G9=""),"",SQRT(POWER(F8-F9,2)+POWER(G8-G9,2))) -> #VALUE! | F8: =IF(A8="","",IF(A8=$A$6,$F$6,MID(L8,38,9))) -> 471496.77 | G8: =IF(A8="","",IF(A8=$A$6,$G$6,MID(L8,22,10))) -> 2507737.72 | L8: в точке X=2507737.7200 Y=471496.7700 Z= 1.9400 | S8: , | T8: 96.88 | W8: =CONCATENATE(A8,S8,F8,S8,G8,S8,T8) -> 3,471496.77,2507737.72,96,88
A9: =IF(L9="",IF(L8="","",$A$6),A8+1) -> 4 | B9: =IF(D9="","",TRUNC(D9)) -> #VALUE! | C9: =IF(D9="","",(D9-B9)*60) -> #VALUE! | D9: =IF(OR(F9="",F10="",G9="",G10=""),"",IF(AND((G9-G10)<0,(F9-F10)<0),ATAN((G9-G10)/(F9-F10))*180/PI(),IF((F9-F10)>0,180+ATAN((G9-G10)/(F9-F10))*180/PI(),360+ATAN((G9-G10)/(F9-F10))*180/PI()))) -> #VALUE! | E9: =IF(OR(F9="",F10="",G9="",G10=""),"",SQRT(POWER(F9-F10,2)+POWER(G9-G10,2))) -> #VALUE! | F9: =IF(A9="","",IF(A9=$A$6,$F$6,MID(L9,38,9))) -> 471492.34 | G9: =IF(A9="","",IF(A9=$A$6,$G$6,MID(L9,22,10))) -> 2507738.97 | L9: в точке X=2507738.9700 Y=471492.3400 Z= 1.9400 | W9: =CONCATENATE(A9,S9,F9,S9,G9,S9,T9) -> 4471492.342507738.97
A10: =IF(L10="",IF(L9="","",$A$6),A9+1) -> 5 | B10: =IF(D10="","",TRUNC(D10)) -> #VALUE! | C10: =IF(D10="","",(D10-B10)*60) -> #VALUE! | D10: =IF(OR(F10="",F11="",G10="",G11=""),"",IF(AND((G10-G11)<0,(F10-F11)<0),ATAN((G10-G11)/(F10-F11))*180/PI(),IF((F10-F11)>0,180+ATAN((G10-G11)/(F10-F11))*180/PI(),360+ATAN((G10-G11)/(F10-F11))*180/PI()))) -> #VALUE! | E10: =IF(OR(F10="",F11="",G10="",G11=""),"",SQRT(POWER(F10-F11,2)+POWER(G10-G11,2))) -> #VALUE! | F10: =IF(A10="","",IF(A10=$A$6,$F$6,MID(L10,38,9))) -> 471491.93 | G10: =IF(A10="","",IF(A10=$A$6,$G$6,MID(L10,22,10))) -> 2507737.52 | L10: в точке X=2507737.5200 Y=471491.9300 Z= 1.9400
A11: =IF(L11="",IF(L10="","",$A$6),A10+1) -> 6 | B11: =IF(D11="","",TRUNC(D11)) -> #VALUE! | C11: =IF(D11="","",(D11-B11)*60) -> #VALUE! | D11: =IF(OR(F11="",F12="",G11="",G12=""),"",IF(AND((G11-G12)<0,(F11-F12)<0),ATAN((G11-G12)/(F11-F12))*180/PI(),IF((F11-F12)>0,180+ATAN((G11-G12)/(F11-F12))*180/PI(),360+ATAN((G11-G12)/(F11-F12))*180/PI()))) -> #VALUE! | E11: =IF(OR(F11="",F12="",G11="",G12=""),"",SQRT(POWER(F11-F12,2)+POWER(G11-G12,2))) -> #VALUE! | F11: =IF(A11="","",IF(A11=$A$6,$F$6,MID(L11,38,9))) -> 471490.17 | G11: =IF(A11="","",IF(A11=$A$6,$G$6,MID(L11,22,10))) -> 2507731.26 | L11: в точке X=2507731.2631 Y=471490.1794 Z= 1.9400
A12: =IF(L12="",IF(L11="","",$A$6),A11+1) -> 1 | B12: =IF(D12="","",TRUNC(D12)) | C12: =IF(D12="","",(D12-B12)*60) | D12: =IF(OR(F12="",F13="",G12="",G13=""),"",IF(AND((G12-G13)<0,(F12-F13)<0),ATAN((G12-G13)/(F12-F13))*180/PI(),IF((F12-F13)>0,180+ATAN((G12-G13)/(F12-F13))*180/PI(),360+ATAN((G12-G13)/(F12-F13))*180/PI()))) | E12: =IF(OR(F12="",F13="",G12="",G13=""),"",SQRT(POWER(F12-F13,2)+POWER(G12-G13,2))) | F12: =IF(A12="","",IF(A12=$A$6,$F$6,MID(L12,38,9))) -> 471494.61 | G12: =IF(A12="","",IF(A12=$A$6,$G$6,MID(L12,22,10))) -> 2507730.00
A13: =IF(L13="",IF(L12="","",$A$6),A12+1) | B13: =IF(D13="","",TRUNC(D13)) | C13: =IF(D13="","",(D13-B13)*60) | D13: =IF(OR(F13="",F14="",G13="",G14=""),"",IF(AND((G13-G14)<0,(F13-F14)<0),ATAN((G13-G14)/(F13-F14))*180/PI(),IF((F13-F14)>0,180+ATAN((G13-G14)/(F13-F14))*180/PI(),360+ATAN((G13-G14)/(F13-F14))*180/PI()))) | E13: =IF(OR(F13="",F14="",G13="",G14=""),"",SQRT(POWER(F13-F14,2)+POWER(G13-G14,2))) | F13: =IF(A13="","",IF(A13=$A$6,$F$6,MID(L13,38,9))) | G13: =IF(A13="","",IF(A13=$A$6,$G$6,MID(L13,22,10)))
A14: =IF(L14="",IF(L13="","",$A$6),A13+1) | B14: =IF(D14="","",TRUNC(D14)) | C14: =IF(D14="","",(D14-B14)*60) | D14: =IF(OR(F14="",F15="",G14="",G15=""),"",IF(AND((G14-G15)<0,(F14-F15)<0),ATAN((G14-G15)/(F14-F15))*180/PI(),IF((F14-F15)>0,180+ATAN((G14-G15)/(F14-F15))*180/PI(),360+ATAN((G14-G15)/(F14-F15))*180/PI()))) | E14: =IF(OR(F14="",F15="",G14="",G15=""),"",SQRT(POWER(F14-F15,2)+POWER(G14-G15,2))) | F14: =IF(A14="","",IF(A14=$A$6,$F$6,MID(L14,38,9))) | G14: =IF(A14="","",IF(A14=$A$6,$G$6,MID(L14,22,10)))
A15: =IF(L15="",IF(L14="","",$A$6),A14+1) | B15: =IF(D15="","",TRUNC(D15)) | C15: =IF(D15="","",(D15-B15)*60) | D15: =IF(OR(F15="",F16="",G15="",G16=""),"",IF(AND((G15-G16)<0,(F15-F16)<0),ATAN((G15-G16)/(F15-F16))*180/PI(),IF((F15-F16)>0,180+ATAN((G15-G16)/(F15-F16))*180/PI(),360+ATAN((G15-G16)/(F15-F16))*180/PI()))) | E15: =IF(OR(F15="",F16="",G15="",G16=""),"",SQRT(POWER(F15-F16,2)+POWER(G15-G16,2))) | F15: =IF(A15="","",IF(A15=$A$6,$F$6,MID(L15,38,9))) | G15: =IF(A15="","",IF(A15=$A$6,$G$6,MID(L15,22,10)))
A16: =IF(L16="",IF(L15="","",$A$6),A15+1) | B16: =IF(D16="","",TRUNC(D16)) | C16: =IF(D16="","",(D16-B16)*60) | D16: =IF(OR(F16="",F17="",G16="",G17=""),"",IF(AND((G16-G17)<0,(F16-F17)<0),ATAN((G16-G17)/(F16-F17))*180/PI(),IF((F16-F17)>0,180+ATAN((G16-G17)/(F16-F17))*180/PI(),360+ATAN((G16-G17)/(F16-F17))*180/PI()))) | E16: =IF(OR(F16="",F17="",G16="",G17=""),"",SQRT(POWER(F16-F17,2)+POWER(G16-G17,2))) | F16: =IF(A16="","",IF(A16=$A$6,$F$6,MID(L16,38,9))) | G16: =IF(A16="","",IF(A16=$A$6,$G$6,MID(L16,22,10)))
A17: =IF(L17="",IF(L16="","",$A$6),A16+1) | B17: =IF(D17="","",TRUNC(D17)) | C17: =IF(D17="","",(D17-B17)*60) | D17: =IF(OR(F17="",F18="",G17="",G18=""),"",IF(AND((G17-G18)<0,(F17-F18)<0),ATAN((G17-G18)/(F17-F18))*180/PI(),IF((F17-F18)>0,180+ATAN((G17-G18)/(F17-F18))*180/PI(),360+ATAN((G17-G18)/(F17-F18))*180/PI()))) | E17: =IF(OR(F17="",F18="",G17="",G18=""),"",SQRT(POWER(F17-F18,2)+POWER(G17-G18,2))) | F17: =IF(A17="","",IF(A17=$A$6,$F$6,MID(L17,37,9))) | G17: =IF(A17="","",IF(A17=$A$6,$G$6,MID(L17,22,10)))
A18: =IF(L18="",IF(L17="","",$A$6),A17+1) | B18: =IF(D18="","",TRUNC(D18)) | C18: =IF(D18="","",(D18-B18)*60) | D18: =IF(OR(F18="",F19="",G18="",G19=""),"",IF(AND((G18-G19)<0,(F18-F19)<0),ATAN((G18-G19)/(F18-F19))*180/PI(),IF((F18-F19)>0,180+ATAN((G18-G19)/(F18-F19))*180/PI(),360+ATAN((G18-G19)/(F18-F19))*180/PI()))) | E18: =IF(OR(F18="",F19="",G18="",G19=""),"",SQRT(POWER(F18-F19,2)+POWER(G18-G19,2))) | F18: =IF(A18="","",IF(A18=$A$6,$F$6,MID(L18,37,9))) | G18: =IF(A18="","",IF(A18=$A$6,$G$6,MID(L18,22,10)))
A19: =IF(L19="",IF(L18="","",$A$6),A18+1) | B19: =IF(D19="","",TRUNC(D19)) | C19: =IF(D19="","",(D19-B19)*60) | D19: =IF(OR(F19="",F20="",G19="",G20=""),"",IF(AND((G19-G20)<0,(F19-F20)<0),ATAN((G19-G20)/(F19-F20))*180/PI(),IF((F19-F20)>0,180+ATAN((G19-G20)/(F19-F20))*180/PI(),360+ATAN((G19-G20)/(F19-F20))*180/PI()))) | E19: =IF(OR(F19="",F20="",G19="",G20=""),"",SQRT(POWER(F19-F20,2)+POWER(G19-G20,2))) | F19: =IF(A19="","",IF(A19=$A$6,$F$6,MID(L19,37,9))) | G19: =IF(A19="","",IF(A19=$A$6,$G$6,MID(L19,22,10)))
A20: =IF(L20="",IF(L19="","",$A$6),A19+1) | B20: =IF(D20="","",TRUNC(D20)) | C20: =IF(D20="","",(D20-B20)*60) | D20: =IF(OR(F20="",F21="",G20="",G21=""),"",IF(AND((G20-G21)<0,(F20-F21)<0),ATAN((G20-G21)/(F20-F21))*180/PI(),IF((F20-F21)>0,180+ATAN((G20-G21)/(F20-F21))*180/PI(),360+ATAN((G20-G21)/(F20-F21))*180/PI()))) | E20: =IF(OR(F20="",F21="",G20="",G21=""),"",SQRT(POWER(F20-F21,2)+POWER(G20-G21,2))) | F20: =IF(A20="","",IF(A20=$A$6,$F$6,MID(L20,37,9))) | G20: =IF(A20="","",IF(A20=$A$6,$G$6,MID(L20,22,10)))
A21: =IF(L21="",IF(L20="","",$A$6),A20+1) | B21: =IF(D21="","",TRUNC(D21)) | C21: =IF(D21="","",(D21-B21)*60) | D21: =IF(OR(F21="",F22="",G21="",G22=""),"",IF(AND((G21-G22)<0,(F21-F22)<0),ATAN((G21-G22)/(F21-F22))*180/PI(),IF((F21-F22)>0,180+ATAN((G21-G22)/(F21-F22))*180/PI(),360+ATAN((G21-G22)/(F21-F22))*180/PI()))) | E21: =IF(OR(F21="",F22="",G21="",G22=""),"",SQRT(POWER(F21-F22,2)+POWER(G21-G22,2))) | F21: =IF(A21="","",IF(A21=$A$6,$F$6,MID(L21,37,9))) | G21: =IF(A21="","",IF(A21=$A$6,$G$6,MID(L21,22,10)))
A22: =IF(L22="",IF(L21="","",$A$6),A21+1) | B22: =IF(D22="","",TRUNC(D22)) | C22: =IF(D22="","",(D22-B22)*60) | D22: =IF(OR(F22="",F23="",G22="",G23=""),"",IF(AND((G22-G23)<0,(F22-F23)<0),ATAN((G22-G23)/(F22-F23))*180/PI(),IF((F22-F23)>0,180+ATAN((G22-G23)/(F22-F23))*180/PI(),360+ATAN((G22-G23)/(F22-F23))*180/PI()))) | E22: =IF(OR(F22="",F23="",G22="",G23=""),"",SQRT(POWER(F22-F23,2)+POWER(G22-G23,2))) | F22: =IF(A22="","",IF(A22=$A$6,$F$6,MID(L22,37,9))) | G22: =IF(A22="","",IF(A22=$A$6,$G$6,MID(L22,22,10)))
A23: =IF(L23="",IF(L22="","",$A$6),A22+1) | B23: =IF(D23="","",TRUNC(D23)) | C23: =IF(D23="","",(D23-B23)*60) | D23: =IF(OR(F23="",F24="",G23="",G24=""),"",IF(AND((G23-G24)<0,(F23-F24)<0),ATAN((G23-G24)/(F23-F24))*180/PI(),IF((F23-F24)>0,180+ATAN((G23-G24)/(F23-F24))*180/PI(),360+ATAN((G23-G24)/(F23-F24))*180/PI()))) | E23: =IF(OR(F23="",F24="",G23="",G24=""),"",SQRT(POWER(F23-F24,2)+POWER(G23-G24,2))) | F23: =IF(A23="","",IF(A23=$A$6,$F$6,MID(L23,37,9))) | G23: =IF(A23="","",IF(A23=$A$6,$G$6,MID(L23,22,10)))
A24: =IF(L24="",IF(L23="","",$A$6),A23+1) | B24: =IF(D24="","",TRUNC(D24)) | C24: =IF(D24="","",(D24-B24)*60) | D24: =IF(OR(F24="",F25="",G24="",G25=""),"",IF(AND((G24-G25)<0,(F24-F25)<0),ATAN((G24-G25)/(F24-F25))*180/PI(),IF((F24-F25)>0,180+ATAN((G24-G25)/(F24-F25))*180/PI(),360+ATAN((G24-G25)/(F24-F25))*180/PI()))) | E24: =IF(OR(F24="",F25="",G24="",G25=""),"",SQRT(POWER(F24-F25,2)+POWER(G24-G25,2))) | F24: =IF(A24="","",IF(A24=$A$6,$F$6,MID(L24,37,9))) | G24: =IF(A24="","",IF(A24=$A$6,$G$6,MID(L24,22,10)))
A25: =IF(L25="",IF(L24="","",$A$6),A24+1) | B25: =IF(D25="","",TRUNC(D25)) | C25: =IF(D25="","",(D25-B25)*60) | D25: =IF(OR(F25="",F26="",G25="",G26=""),"",IF(AND((G25-G26)<0,(F25-F26)<0),ATAN((G25-G26)/(F25-F26))*180/PI(),IF((F25-F26)>0,180+ATAN((G25-G26)/(F25-F26))*180/PI(),360+ATAN((G25-G26)/(F25-F26))*180/PI()))) | E25: =IF(OR(F25="",F26="",G25="",G26=""),"",SQRT(POWER(F25-F26,2)+POWER(G25-G26,2))) | F25: =IF(A25="","",IF(A25=$A$6,$F$6,MID(L25,37,9))) | G25: =IF(A25="","",IF(A25=$A$6,$G$6,MID(L25,22,10)))
A26: =IF(L26="",IF(L25="","",$A$6),A25+1) | B26: =IF(D26="","",TRUNC(D26)) | C26: =IF(D26="","",(D26-B26)*60) | D26: =IF(OR(F26="",F27="",G26="",G27=""),"",IF(AND((G26-G27)<0,(F26-F27)<0),ATAN((G26-G27)/(F26-F27))*180/PI(),IF((F26-F27)>0,180+ATAN((G26-G27)/(F26-F27))*180/PI(),360+ATAN((G26-G27)/(F26-F27))*180/PI()))) | E26: =IF(OR(F26="",F27="",G26="",G27=""),"",SQRT(POWER(F26-F27,2)+POWER(G26-G27,2))) | F26: =IF(A26="","",IF(A26=$A$6,$F$6,MID(L26,37,9))) | G26: =IF(A26="","",IF(A26=$A$6,$G$6,MID(L26,22,10)))
A27: =IF(L27="",IF(L26="","",$A$6),A26+1) | B27: =IF(D27="","",TRUNC(D27)) | C27: =IF(D27="","",(D27-B27)*60) | D27: =IF(OR(F27="",F28="",G27="",G28=""),"",IF(AND((G27-G28)<0,(F27-F28)<0),ATAN((G27-G28)/(F27-F28))*180/PI(),IF((F27-F28)>0,180+ATAN((G27-G28)/(F27-F28))*180/PI(),360+ATAN((G27-G28)/(F27-F28))*180/PI()))) | E27: =IF(OR(F27="",F28="",G27="",G28=""),"",SQRT(POWER(F27-F28,2)+POWER(G27-G28,2))) | F27: =IF(A27="","",IF(A27=$A$6,$F$6,MID(L27,37,9))) | G27: =IF(A27="","",IF(A27=$A$6,$G$6,MID(L27,22,10)))
A28: =IF(L28="",IF(L27="","",$A$6),A27+1) | B28: =IF(D28="","",TRUNC(D28)) | C28: =IF(D28="","",(D28-B28)*60) | D28: =IF(OR(F28=0,F29=0,G28=0,G29=0),"",IF(AND((G28-G29)<0,(F28-F29)<0),ATAN((G28-G29)/(F28-F29))*180/PI(),IF((F28-F29)>0,180+ATAN((G28-G29)/(F28-F29))*180/PI(),360+ATAN((G28-G29)/(F28-F29))*180/PI()))) | E28: =IF(OR(F28=0,F29=0,G28=0,G29=0),"",SQRT(POWER(F28-F29,2)+POWER(G28-G29,2))) | F28: =IF(A28="","",IF(A28=$A$6,$F$6,MID(L28,38,9))) | G28: =IF(A28="","",IF(A28=$A$6,$G$6,MID(L28,22,10)))
A31: Условный номер земельного участка | F31: 29:15:061201:4506:ЗУ1
A32: Площадь земельного участка | G32: 84 | H32: м2
A33: Обозначение характерных точек границ | B33: Дирекционный угол | D33: Д. угол в долях | E33: Расстояние | F33: Координаты
B34: 0 | C34: / | D34: 0 | E34: М | F34: Х | G34: У
A35: 1 | B35: =IF(D35="","",TRUNC(D35)) -> #VALUE! | C35: =IF(D35="","",(D35-B35)*60) -> #VALUE! | D35: =IF(OR(F35=0,F36=0,G35=0,G36=0),"",IF(AND((G35-G36)<0,(F35-F36)<0),ATAN((G35-G36)/(F35-F36))*180/PI(),IF((F35-F36)>0,180+ATAN((G35-G36)/(F35-F36))*180/PI(),360+ATAN((G35-G36)/(F35-F36))*180/PI()))) -> #VALUE! | E35: =IF(OR(F35=0,F36=0,G35=0,G36=0),"",SQRT(POWER(F35-F36,2)+POWER(G35-G36,2))) -> #VALUE! | F35: =MID(L35,38,9) -> 471663.69 | G35: =MID(L35,22,10) -> 2506544.60 | L35: в точке X=2506544.6000 Y=471663.6900 Z= 0.0000
A36: 2 | B36: =IF(D36="","",TRUNC(D36)) -> #VALUE! | C36: =IF(D36="","",(D36-B36)*60) -> #VALUE! | D36: =IF(OR(F36=0,F37=0,G36=0,G37=0),"",IF(AND((G36-G37)<0,(F36-F37)<0),ATAN((G36-G37)/(F36-F37))*180/PI(),IF((F36-F37)>0,180+ATAN((G36-G37)/(F36-F37))*180/PI(),360+ATAN((G36-G37)/(F36-F37))*180/PI()))) -> #VALUE! | E36: =IF(OR(F36=0,F37=0,G36=0,G37=0),"",SQRT(POWER(F36-F37,2)+POWER(G36-G37,2))) -> #VALUE! | F36: =MID(L36,38,9) -> 471655.04 | G36: =MID(L36,22,10) -> 2506556.60 | L36: в точке X=2506556.6000 Y=471655.0400 Z= 0.0000
A37: 3 | B37: =IF(D37="","",TRUNC(D37)) -> #VALUE! | C37: =IF(D37="","",(D37-B37)*60) -> #VALUE! | D37: =IF(OR(F37="",F38="",G37="",G38=""),"",IF(AND((G37-G38)<0,(F37-F38)<0),ATAN((G37-G38)/(F37-F38))*180/PI(),IF((F37-F38)>0,180+ATAN((G37-G38)/(F37-F38))*180/PI(),360+ATAN((G37-G38)/(F37-F38))*180/PI()))) -> #VALUE! | E37: =IF(OR(F37="",F38="",G37="",G38=""),"",SQRT(POWER(F37-F38,2)+POWER(G37-G38,2))) -> #VALUE! | F37: =IF(A37="","",IF(A37=$A$35,$F$35,MID(L37,38,9))) -> 471650.15 | G37: =IF(A37="","",IF(A37=$A$35,$G$35,MID(L37,22,10))) -> 2506553.20 | L37: в точке X=2506553.2000 Y=471650.1500 Z= 0.0000
A38: 4 | B38: =IF(D38="","",TRUNC(D38)) -> #VALUE! | C38: =IF(D38="","",(D38-B38)*60) -> #VALUE! | D38: =IF(OR(F38="",F39="",G38="",G39=""),"",IF(AND((G38-G39)<0,(F38-F39)<0),ATAN((G38-G39)/(F38-F39))*180/PI(),IF((F38-F39)>0,180+ATAN((G38-G39)/(F38-F39))*180/PI(),360+ATAN((G38-G39)/(F38-F39))*180/PI()))) -> #VALUE! | E38: =IF(OR(F38="",F39="",G38="",G39=""),"",SQRT(POWER(F38-F39,2)+POWER(G38-G39,2))) -> #VALUE! | F38: =IF(A38="","",IF(A38=$A$35,$F$35,MID(L38,38,9))) -> 471653.06 | G38: =IF(A38="","",IF(A38=$A$35,$G$35,MID(L38,22,10))) -> 2506553.73 | L38: в точке X=2506553.7300 Y=471653.0600 Z= 0.0000
A39: 5 | B39: =IF(D39="","",TRUNC(D39)) -> #VALUE! | C39: =IF(D39="","",(D39-B39)*60) -> #VALUE! | D39: =IF(OR(F39="",F40="",G39="",G40=""),"",IF(AND((G39-G40)<0,(F39-F40)<0),ATAN((G39-G40)/(F39-F40))*180/PI(),IF((F39-F40)>0,180+ATAN((G39-G40)/(F39-F40))*180/PI(),360+ATAN((G39-G40)/(F39-F40))*180/PI()))) -> #VALUE! | E39: =IF(OR(F39="",F40="",G39="",G40=""),"",SQRT(POWER(F39-F40,2)+POWER(G39-G40,2))) -> #VALUE! | F39: =IF(A39="","",IF(A39=$A$35,$F$35,MID(L39,38,9))) -> 471661.60 | G39: =IF(A39="","",IF(A39=$A$35,$G$35,MID(L39,22,10))) -> 2506543.15 | L39: в точке X=2506543.1500 Y=471661.6000 Z= 0.0000
A40: 1 | B40: =IF(D40="","",TRUNC(D40)) | C40: =IF(D40="","",(D40-B40)*60) | D40: =IF(OR(F40="",F41="",G40="",G41=""),"",IF(AND((G40-G41)<0,(F40-F41)<0),ATAN((G40-G41)/(F40-F41))*180/PI(),IF((F40-F41)>0,180+ATAN((G40-G41)/(F40-F41))*180/PI(),360+ATAN((G40-G41)/(F40-F41))*180/PI()))) | E40: =IF(OR(F40="",F41="",G40="",G41=""),"",SQRT(POWER(F40-F41,2)+POWER(G40-G41,2))) | F40: =IF(A40="","",IF(A40=$A$35,$F$35,MID(L40,38,9))) -> 471663.69 | G40: =IF(A40="","",IF(A40=$A$35,$G$35,MID(L40,22,10))) -> 2506544.60
A42: 6 | B42: =IF(D42="","",TRUNC(D42)) -> #VALUE! | C42: =IF(D42="","",(D42-B42)*60) -> #VALUE! | D42: =IF(OR(F42=0,F43=0,G42=0,G43=0),"",IF(AND((G42-G43)<0,(F42-F43)<0),ATAN((G42-G43)/(F42-F43))*180/PI(),IF((F42-F43)>0,180+ATAN((G42-G43)/(F42-F43))*180/PI(),360+ATAN((G42-G43)/(F42-F43))*180/PI()))) -> #VALUE! | E42: =IF(OR(F42=0,F43=0,G42=0,G43=0),"",SQRT(POWER(F42-F43,2)+POWER(G42-G43,2))) -> #VALUE! | F42: =MID(L42,38,9) -> 471639.68 | G42: =MID(L42,22,10) -> 2506527.87 | L42: в точке X=2506527.8700 Y=471639.6800 Z= 0.0000
A43: 7 | B43: =IF(D43="","",TRUNC(D43)) -> #VALUE! | C43: =IF(D43="","",(D43-B43)*60) -> #VALUE! | D43: =IF(OR(F43=0,F44=0,G43=0,G44=0),"",IF(AND((G43-G44)<0,(F43-F44)<0),ATAN((G43-G44)/(F43-F44))*180/PI(),IF((F43-F44)>0,180+ATAN((G43-G44)/(F43-F44))*180/PI(),360+ATAN((G43-G44)/(F43-F44))*180/PI()))) -> #VALUE! | E43: =IF(OR(F43=0,F44=0,G43=0,G44=0),"",SQRT(POWER(F43-F44,2)+POWER(G43-G44,2))) -> #VALUE! | F43: =MID(L43,38,9) -> 471631.08 | G43: =MID(L43,22,10) -> 2506539.91 | L43: в точке X=2506539.9100 Y=471631.0800 Z= 0.0000
...

Sheet Титул
D1: Всего листов
A2: МЕЖЕВОЙ ПЛАН | B2: Заполняется специалистом органа кадастрового учета
B3: регистрационный № _______________________________________ __________________ ______________________________________ (подпись) (инициалы, фамилия) « ______ » ______________________ г.
A4: Титульный лист
A5: 1. Межевой план подготовлен в результате выполнения кадастровых работ в связи с:
A6: образованием земельного участка из земель, находящихся в государственной собственности,
A7: расположенного:
A8: 2. Цель кадастровых работ:
A9: -
A10: 3. Сведения о заказчике кадастровых работ:
A11: Шарова Елена Сергеевна
A12: (фамилия, имя, отчество (при наличии отчества) физического лица, полное наименование юридического лица, органа государственной власти, органа местного самоуправления, иностранного юридического лица с указанием страны его регистрации (инкорпорации)
A13: Подпись _____________________Е.С. Шарова | C13: Дата: | D13: =D21 -> 43803
A14: Место для оттиска печати заказчика кадастровых работ
A15: 4. Сведения о кадастровом инженере:
A16: Фамилия, имя, отчество (при наличии отчества) | C16: Зуев Андрей Николаевич индивидуальный предприниматель
A17: № квалификационного аттестата кадастрового инженера | C17: 29-10-51
A18: Контактный телефон | B18: + 7 909 55 22 052, 8(818-32)7-15-83
A19: Почтовый адрес и адрес электронной почты, по которым осуществляется связь с кадастровым инженером:
A20: 164288, Архангельская область, Плесецкий район, п. Савинский, ул. Октябрьская, дом 18, квартира 71., получатель - Зуев Андрей Николаевич, электронный адрес: zuew23@mail.ru
A21: Подпись _______________________А.Н. Зуев | C21: Дата: | D21: =TODAY() -> 43803
A22: Место для оттиска печати кадастрового инженера

Sheet Содерж
F1: Лист № | G1: 2
A2: МЕЖЕВОЙ ПЛАН
A3: Содержание
A4: № п/п | B4: Разделы межевого плана | G4: Номера листов
A5: 1 | B5: 2 | G5: 3
A6: 1 | B6: Титульный лист | G6: 1
A7: 2 | B7: Содержание | G7: 2
A8: 3 | B8: Исходные данные | G8: 3
A9: 4 | B9: Сведения о выполненных измерениях и расчетах | G9: 4
A10: 5 | B10: Сведения об образуемых земельных участках и их частях | G10: 5, стр. 1
A11: 6 | B11: Сведения об образуемых земельных участках и их частях | G11: 5, стр. 2
A12: 7 | B12: Сведения о земельных участках, посредством которых обеспечивается доступ к образуемым или измененным земельным участкам | G12: 6
A13: 8 | B13: Схема геодезических построений | G13: 7
A14: 9 | B14: Схема расположения земельных участков | G14: 8
A15: 10 | B15: Чертеж земельных участков и их частей | G15: 9
B16: Приложения
B17: Постановление администрации МО "Плесецкий муниципальный район" от
B18: 22.04.2008 г. | C18: № | D18: 390 | E18: (копия)
B19: Постановление администрации МО "Плесецкое" от
B20: 12.04.2012 г. | C20: № | D20: 228 | E20: (копия)
B21: Схема расположения земельного участка от | D21: =B20 -> 12.04.2012 г. | E21: (копия)

Sheet Исх данные
I1: Лист № | J1: 3
A2: МЕЖЕВОЙ ПЛАН
A3: Исходные данные
A4: 1. Перечень документов, использованных при подготовке межевого плана
A5: № п/п | B5: Наименование документа | F5: Реквизиты документа
A6: 1 | B6: 2 | F6: 3
A7: 1 | B7: Кадастровый план территории | F7: № | G7: 2900/201/11-48947 | I7: от | J7: 26.09.2011 г.
A8: 3 | B8: Постановление МО "Плесецкое" | F8: № | G8: =Содерж!D20 -> 228 | I8: от | J8: =Содерж!B20 -> 12.04.2012 г.
A9: 4 | B9: Схема расположения земельного участка | F9: Приложение к постановлению | I9: от | J9: =J8 -> 12.04.2012 г.
A10: 2. Сведения о геодезической основе, использованной при подготовке проекта межевания территории
A11: Система координат | D11: МСК29
A12: № п/п | B12: Название пункта и тип знака геодезической сети | D12: Класс геодезической сети | F12: Координаты, м
F13: X | I13: Y
A14: 1 | B14: 2 | D14: 3 | F14: 4 | I14: 5
A15: 1 | B15: 585 | D15: 1 кл | F15: 446918.59 | I15: 2514466.1
A16: 2 | B16: 614 | D16: 3 кл | F16: 454792.76 | I16: 2512774.2
A17: 2 | B17: 615 | D17: 4 кл | F17: 454685.45 | I17: 2516752
A18: 3. Сведения о средствах измерений
A19: № п/п | B19: Наименование прибора (инструмента, аппаратуры) | E19: Реквизиты сертификата прибора(инструмента, аппаратуры), при наличиии такого сертификата | I19: Реквизиты свидетельства о поверке прибора (инструмента, аппаратуры)
A20: 1 | B20: 2 | E20: 3 | I20: 4
A21: 1 | B21: Тахеометр Nikon | E21: - | I21: Свидетельство о поверке № 152561 от 02.03.2017 г. действительно до 02.03.2017 г.
A22: 2 | B22: EPOCH - 10 | E22: - | I22: Свидетельство о поверке № 152832 от 02.03.2017 г. действительно до 02.03.2017 г.
A23: 3 | B23: EPOCH - 10 | E23: - | I23: Свидетельство о поверке № 152833 от 02.03.2017 г. действительно до 02.03.2017 г.
A24: 4 | B24: EPOCH - 10 | E24: - | I24: Свидетельство о поверке № 152834 от 02.03.2017 г. действительно до 02.03.2017 г.
A25: 4. Сведения о наличии зданий, сооружений, объектов незавершенного строительства на исходных или измененных земельных участках
A26: № п/п | B26: Кадастровый номер земельного участка | F26: Кадастровые или иные номера зданий,сооружений,объектов незавершенного стороительства, расположенных на земельном участке
A27: 1 | B27: 2 | F27: 3
A28: - | B28: - | F28: -
A29: 5. Сведения о частях исходных, измененных или уточняемых земельных участков
A30: № п/п | B30: Кадастровый номер земельного участка | F30: Учетные номера частей земельного участка
A31: 1 | B31: 2 | F31: 3
A32: - | B32: - | F32: -

Sheet изм и расчеты
H1: Лист № | I1: 4
A2: МЕЖЕВОЙ ПЛАН
A3: Сведения о выполненных измерениях и расчетах
A4: 1. Метод определения координат характерных точек границ земельных участков и их частей
A5: № п/п | B5: Кадастровый номер или обозначение земельного участка | D5: Метод определения координат
A6: 1 | B6: 2 | D6: 3
A7: 1 | B7: :ЗУ1 | D7: геодезический метод
A8: 2. Точность положения характерных точек границ земельных участков
A9: № п/п | B9: Кадастровый номер или обозначение земельного участка | D9: Формулы, примененные для расчета средней квадратической погрешности положения характерных точек границ (Mt), м
A10: 1 | B10: 2 | D10: 3
A11: 1 | B11: =B7 -> :ЗУ1 | D11: Mt=√m02+mi2= | E11: √ | F11: =POWER((RAND()*0.1)/10,0.5) -> 0.067684654 | G11: =POWER(POWER(I11,2)-POWER(F11,2),0.5) -> 0.073612415 | H11: = | I11: 0.1
A12: 3. Точность положения характерных точек границ частей земельных участков
A13: № п/п | B13: Кадастровый номер или обозначение земельного участка | D13: Учетный номер или обозначение части | F13: Формулы, примененные для расчета средней квадратической погрешности положения характерных точек границ (Mt), м
A14: 1 | B14: 2 | D14: 3 | F14: 4
A15: - | B15: - | D15: - | F15: -
A16: 4. Точность определения площади земельных участков
A17: № п/п | B17: Кадастровый номер или обозначение земельного участка | D17: Площадь (Р), м2 | E17: Формулы, примененные для расчета предельно допустимой погрешности определения площади земельного участка (∆Р), м2
A18: 1 | B18: 2 | D18: 3 | E18: 4
A19: 1 | B19: =B11 -> :ЗУ1 | D19: 696 | E19: =CONCATENATE("ΔPдоп = 3,5*",I11,"√ ",D19,"=") -> ΔPдоп = 3,5*0,1√ 696= | I19: =3.5*(I11)*SQRT(D19) -> 9.2336342
A20: 5. Точность определения площади частей земельных участков
A21: № п/п | B21: Кадастровый номер или обозначение земельного участка | C21: Учетный номер или обозначение части | E21: Площадь (Р), м2 | G21: Формулы, примененные для расчета предельно допустимой погрешности определения площади части земельного участка (∆Р), м2
A22: 1 | B22: 2 | C22: 3 | E22: 4 | G22: 5
A23: - | B23: - | C23: =D15 -> - | E23: - | G23: -

Sheet образование
N1: Лист № | O1: 5
A2: МЕЖЕВОЙ ПЛАН
A3: Сведения об образуемых земельных участках и их частях
A4: 1. Сведения о характерных точках границ образуемых земельных участков
A5: Обозначение земельного участка | J5: ='изм и расчеты'!B7 -> :ЗУ1
A6: Обозначение характерных точек границы | B6: Координаты, м | J6: Средняя квадратическая погрешность положения характерной точки (Mt), м | N6: Описание
B7: X | I7: Y
A8: 1 | B8: 2 | I8: 3 | J8: 4 | N8: 5
A9: 1 | B9: =VLOOKUP($A9,'Каталог коорд'!A6:G28,8,FALSE) -> #REF! | I9: =VLOOKUP($A9,'Каталог коорд'!A6:G28,9,FALSE) -> #REF! | J9: 0.1 | N9: -
A10: 2 | B10: =VLOOKUP($A10,'Каталог коорд'!A7:G29,8,FALSE) -> #REF! | I10: =VLOOKUP($A10,'Каталог коорд'!A7:G29,9,FALSE) -> #REF! | J10: 0.2 | K10: - | N10: -
A11: 3 | B11: =VLOOKUP($A11,'Каталог коорд'!A7:G29,8,FALSE) -> #REF! | I11: =VLOOKUP($A11,'Каталог коорд'!A7:G29,9,FALSE) -> #REF! | J11: 0.2 | K11: - | N11: -
A12: 4 | B12: =VLOOKUP($A12,'Каталог коорд'!A8:G29,8,FALSE) -> #REF! | I12: =VLOOKUP($A12,'Каталог коорд'!A8:G29,9,FALSE) -> #REF! | J12: 0.2 | K12: - | N12: -
A13: 5 | B13: =VLOOKUP($A13,'Каталог коорд'!A9:G29,8,FALSE) -> #REF! | I13: =VLOOKUP($A13,'Каталог коорд'!A9:G29,9,FALSE) -> #REF! | J13: 0.2 | K13: - | N13: -
A14: 6 | B14: =VLOOKUP($A14,'Каталог коорд'!A9:G29,8,FALSE) -> #REF! | I14: =VLOOKUP($A14,'Каталог коорд'!A9:G29,9,FALSE) -> #REF! | J14: 0.2 | K14: - | N14: -
A15: 1 | B15: =VLOOKUP($A15,'Каталог коорд'!A10:G29,8,FALSE) -> #REF! | I15: =VLOOKUP($A15,'Каталог коорд'!A10:G29,9,FALSE) -> #REF! | J15: 0.2 | K15: - | N15: -
A16: 8 | B16: =VLOOKUP($A16,'Каталог коорд'!$A$6:$E29,6,FALSE) -> #N/A | I16: =VLOOKUP($A16,'Каталог коорд'!$A$6:$E29,7,FALSE) -> #N/A | J16: 0.2 | K16: -
A17: 9 | B17: =VLOOKUP($A17,'Каталог коорд'!$A$6:$E29,6,FALSE) -> #N/A | I17: =VLOOKUP($A17,'Каталог коорд'!$A$6:$E29,7,FALSE) -> #N/A | J17: 0.2 | K17: -
B18: =VLOOKUP($A18,'Каталог коорд'!$A$6:$E29,6,FALSE) -> #N/A | I18: =VLOOKUP($A18,'Каталог коорд'!$A$6:$E29,7,FALSE) -> #N/A | J18: 0.2 | K18: -
A19: 2. Сведения о частях границ образуемых земельных участков
A20: Обозначение земельного участка | J20: =J5 -> :ЗУ1
A21: Обозначение части границы | H21: Горизонтальное проложение (S), м | J21: Описание прохождения части границы
A22: от т. | B22: до т.
A23: 1 | B23: 2 | H23: 3 | J23: 4
A24: =A9 -> 1 | B24: =A10 -> 2 | C24: =VLOOKUP($A24,$A$9:$I$18,2,FALSE) -> #REF! | D24: =VLOOKUP($A24,$A$9:$I$18,9,FALSE) -> #REF! | E24: =VLOOKUP($B24,$A$9:$I$18,2,FALSE) -> #REF! | F24: =VLOOKUP($B24,$A$9:$I$18,9,FALSE) -> #REF! | G24: =IF(OR(A24=0,B24=0),"",IF(AND((D24-F24)<0,(C24-E24)<0),ATAN((D24-F24)/(C24-E24))*180/PI(),IF((C24-E24)>0,180+ATAN((D24-F24)/(C24-E24))*180/PI(),360+ATAN((D24-F24)/(C24-E24))*180/PI()))) -> #REF! | H24: =IF(OR(A24=0,B24=0),"",SQRT(POWER(C24-E24,2)+POWER(D24-F24,2))) -> #REF! | J24: -
A25: =A10 -> 2 | B25: =A11 -> 3 | C25: =VLOOKUP($A25,$A$9:$I$18,2,FALSE) -> #REF! | D25: =VLOOKUP($A25,$A$9:$I$18,9,FALSE) -> #REF! | E25: =VLOOKUP($B25,$A$9:$I$18,2,FALSE) -> #REF! | F25: =VLOOKUP($B25,$A$9:$I$18,9,FALSE) -> #REF! | G25: =IF(OR(A25=0,B25=0),"",IF(AND((D25-F25)<0,(C25-E25)<0),ATAN((D25-F25)/(C25-E25))*180/PI(),IF((C25-E25)>0,180+ATAN((D25-F25)/(C25-E25))*180/PI(),360+ATAN((D25-F25)/(C25-E25))*180/PI()))) -> #REF! | H25: =IF(OR(A25=0,B25=0),"",SQRT(POWER(C25-E25,2)+POWER(D25-F25,2))) -> #REF! | J25: -
A26: =A11 -> 3 | B26: =A12 -> 4 | C26: =VLOOKUP($A26,$A$9:$I$18,2,FALSE) -> #REF! | D26: =VLOOKUP($A26,$A$9:$I$18,9,FALSE) -> #REF! | E26: =VLOOKUP($B26,$A$9:$I$18,2,FALSE) -> #REF! | F26: =VLOOKUP($B26,$A$9:$I$18,9,FALSE) -> #REF! | G26: =IF(OR(A26=0,B26=0),"",IF(AND((D26-F26)<0,(C26-E26)<0),ATAN((D26-F26)/(C26-E26))*180/PI(),IF((C26-E26)>0,180+ATAN((D26-F26)/(C26-E26))*180/PI(),360+ATAN((D26-F26)/(C26-E26))*180/PI()))) -> #REF! | H26: =IF(OR(A26=0,B26=0),"",SQRT(POWER(C26-E26,2)+POWER(D26-F26,2))) -> #REF! | J26: -
A27: =A12 -> 4 | B27: =A13 -> 5 | C27: =VLOOKUP($A27,$A$9:$I$18,2,FALSE) -> #REF! | D27: =VLOOKUP($A27,$A$9:$I$18,9,FALSE) -> #REF! | E27: =VLOOKUP($B27,$A$9:$I$18,2,FALSE) -> #REF! | F27: =VLOOKUP($B27,$A$9:$I$18,9,FALSE) -> #REF! | G27: =IF(OR(A27=0,B27=0),"",IF(AND((D27-F27)<0,(C27-E27)<0),ATAN((D27-F27)/(C27-E27))*180/PI(),IF((C27-E27)>0,180+ATAN((D27-F27)/(C27-E27))*180/PI(),360+ATAN((D27-F27)/(C27-E27))*180/PI()))) -> #REF! | H27: =IF(OR(A27=0,B27=0),"",SQRT(POWER(C27-E27,2)+POWER(D27-F27,2))) -> #REF! | J27: -
A28: =A13 -> 5 | B28: =A14 -> 6 | C28: =VLOOKUP($A28,$A$9:$I$18,2,FALSE) -> #REF! | D28: =VLOOKUP($A28,$A$9:$I$18,9,FALSE) -> #REF! | E28: =VLOOKUP($B28,$A$9:$I$18,2,FALSE) -> #REF! | F28: =VLOOKUP($B28,$A$9:$I$18,9,FALSE) -> #REF! | G28: =IF(OR(A28=0,B28=0),"",IF(AND((D28-F28)<0,(C28-E28)<0),ATAN((D28-F28)/(C28-E28))*180/PI(),IF((C28-E28)>0,180+ATAN((D28-F28)/(C28-E28))*180/PI(),360+ATAN((D28-F28)/(C28-E28))*180/PI()))) -> #REF! | H28: =IF(OR(A28=0,B28=0),"",SQRT(POWER(C28-E28,2)+POWER(D28-F28,2))) -> #REF! | J28: -
A29: =A14 -> 6 | B29: =A15 -> 1 | C29: =VLOOKUP($A29,$A$9:$I$18,2,FALSE) -> #REF! | D29: =VLOOKUP($A29,$A$9:$I$18,9,FALSE) -> #REF! | E29: =VLOOKUP($B29,$A$9:$I$18,2,FALSE) -> #REF! | F29: =VLOOKUP($B29,$A$9:$I$18,9,FALSE) -> #REF! | G29: =IF(OR(A29=0,B29=0),"",IF(AND((D29-F29)<0,(C29-E29)<0),ATAN((D29-F29)/(C29-E29))*180/PI(),IF((C29-E29)>0,180+ATAN((D29-F29)/(C29-E29))*180/PI(),360+ATAN((D29-F29)/(C29-E29))*180/PI()))) -> #REF! | H29: =IF(OR(A29=0,B29=0),"",SQRT(POWER(C29-E29,2)+POWER(D29-F29,2))) -> #REF! | J29: -
A30: =A15 -> 1 | B30: =A16 -> 8 | C30: =VLOOKUP($A30,$A$9:$I$18,2,FALSE) -> #REF! | D30: =VLOOKUP($A30,$A$9:$I$18,9,FALSE) -> #REF! | E30: =VLOOKUP($B30,$A$9:$I$18,2,FALSE) -> #N/A | F30: =VLOOKUP($B30,$A$9:$I$18,9,FALSE) -> #N/A | G30: =IF(OR(A30=0,B30=0),"",IF(AND((D30-F30)<0,(C30-E30)<0),ATAN((D30-F30)/(C30-E30))*180/PI(),IF((C30-E30)>0,180+ATAN((D30-F30)/(C30-E30))*180/PI(),360+ATAN((D30-F30)/(C30-E30))*180/PI()))) -> #REF! | H30: =IF(OR(A30=0,B30=0),"",SQRT(POWER(C30-E30,2)+POWER(D30-F30,2))) -> #REF! | J30: -
A31: =A16 -> 8 | B31: =A17 -> 9 | C31: =VLOOKUP($A31,$A$9:$I$18,2,FALSE) -> #N/A | D31: =VLOOKUP($A31,$A$9:$I$18,9,FALSE) -> #N/A | E31: =VLOOKUP($B31,$A$9:$I$18,2,FALSE) -> #N/A | F31: =VLOOKUP($B31,$A$9:$I$18,9,FALSE) -> #N/A | G31: =IF(OR(A31=0,B31=0),"",IF(AND((D31-F31)<0,(C31-E31)<0),ATAN((D31-F31)/(C31-E31))*180/PI(),IF((C31-E31)>0,180+ATAN((D31-F31)/(C31-E31))*180/PI(),360+ATAN((D31-F31)/(C31-E31))*180/PI()))) -> #N/A | H31: =IF(OR(A31=0,B31=0),"",SQRT(POWER(C31-E31,2)+POWER(D31-F31,2))) -> #N/A | J31: -
A32: =A17 -> 9 | B32: =A18 -> 0 | C32: =VLOOKUP($A32,$A$9:$I$18,2,FALSE) -> #N/A | D32: =VLOOKUP($A32,$A$9:$I$18,9,FALSE) -> #N/A | E32: =VLOOKUP($B32,$A$9:$I$18,2,FALSE) -> #N/A | F32: =VLOOKUP($B32,$A$9:$I$18,9,FALSE) -> #N/A | G32: =IF(OR(A32=0,B32=0),"",IF(AND((D32-F32)<0,(C32-E32)<0),ATAN((D32-F32)/(C32-E32))*180/PI(),IF((C32-E32)>0,180+ATAN((D32-F32)/(C32-E32))*180/PI(),360+ATAN((D32-F32)/(C32-E32))*180/PI()))) | H32: =IF(OR(A32=0,B32=0),"",SQRT(POWER(C32-E32,2)+POWER(D32-F32,2))) | J32: -
A33: 3. Сведения о местоположении границ частей образуемых земельных участков
A34: Обозначение земельного участка | J34: =J20 -> :ЗУ1
A35: Учетный номер или обозначение части | J35: -
A36: Обозначение характерных точек границы | B36: Координаты, м | J36: Средняя квадратическая погрешность положения характерной точки (М), м | N36: Описание закрепления точки
B37: X | I37: Y
A38: 1 | B38: 2 | I38: 3 | J38: 4 | N38: 5
A39: - | B39: - | I39: - | J39: - | N39: -
A40: 8 | B40: =VLOOKUP(A40,'Каталог коорд'!A7:G31,8,FALSE) -> #N/A | I40: =VLOOKUP($A10,'Каталог коорд'!A7:G29,9,FALSE) -> #REF! | J40: 0.2
...

Sheet доступ
D1: Лист № | E1: 6
A2: МЕЖЕВОЙ ПЛАН
A3: Сведения о земельных участках, посредством которых обеспечивается доступ к образуемым или измененным земельным участкам
A5: № п/п | B5: Кадастровый номер или обозначение земельного участка, для которого обеспечивается доступ | C5: Кадастровый номер или обозначение земельного участка, посредством которого обеспечивается доступ
A6: 1 | B6: 2 | C6: 3
A7: 1 | B7: ='изм и расчеты'!B7:C7 -> :ЗУ1 | C7: земли общего пользования

Sheet Лист1
A2: n, шт. | B2: Sn, m | C2: Sn, m | D2: Sn, m | E2: Sn, m | F2: Sn, m | H2: ΣSn, m | I2: L, m | J2: m0 | K2: m1 | L2: Мt
A3: =COUNT(B3:F3) -> 5 | B3: 500 | C3: 500 | D3: 500 | E3: 500 | F3: 500 | H3: =SUM(B3:F3) -> 2500 | I3: 1000 | J3: =POWER(0.000009*A3+25*POWER(H3,2)*(A3+3)/(12*POWER(206265,2)),0.5) -> 0.049933692 | K3: =POWER(0.000009+25*POWER(I3,2)/POWER(206265,2),0.5) -> 0.024425594 | L3: =POWER(POWER(J3,2)+POWER(K3,2),0.5) -> 0.055587618
